<?xml version='1.0' encoding='UTF-8'?>
<!-- This file has been generated using freeze_urdf_joints script to adjust some joints.
Option joint_to_freeze_value was:
{
 "AdjustableRightSagittalHipJoint":-0.023172725985553477,
 "AdjustableLeftSagittalHipJoint":-0.023172725985553477,
 "AdjustableLeftSagittalKneeJoint":0.027,
 "AdjustableRightSagittalKneeJoint":0.027
}
-->
<!--
Thigh setting:	443.0
Shank setting:	418.0
-->
<!--
    Total height of the person is: 1.84 m.
    Total mass of the person is: 75 kg.
    Total mass of the system is: 149.814261067 kg.
    Patient offset from exoskeleton is: 0.0 m.
-->
<robot name="v5-4">
  <joint name="RightMetatarsusJoint" type="fixed">
    <origin xyz="0.103821248695 0.0 -0.277177122383" rpy="1.58358451956e-18 0.663225115758 -1.8092540875e-33"/>
    <axis xyz="0.0 0.0 0.0"/>
    <parent link="RightHenkeAnkleLink"/>
    <child link="RightMetatarsus"/>
  </joint>
  <joint name="LeftFrontalHipJoint" type="revolute">
    <origin xyz="0.0 0.089 0.0" rpy="0.0 0.0 0.0"/>
    <axis xyz="1.0 0.0 0.0"/>
    <parent link="PelvisLink"/>
    <child link="LeftFrontalHipLink"/>
    <limit effort="350.0" lower="-0.174532925199" upper="0.296705972839" velocity="2.61799387799"/>
  </joint>
  <joint name="LeftExternalToeJoint" type="fixed">
    <origin xyz="0.0958867916141 0.0358003865588 -0.246866699025" rpy="5.0054690685e-15 0.663225115758 6.86835455008e-15"/>
    <axis xyz="0.0 0.0 0.0"/>
    <parent link="LeftHenkeAnkleLink"/>
    <child link="LeftExternalToe"/>
  </joint>
  <joint name="LeftHenkeAnkleJoint" type="revolute">
    <origin xyz="0.0 0.0 0.0" rpy="-2.978350228e-17 -0.663225115758 0.0"/>
    <axis xyz="1.0 0.0 0.0"/>
    <parent link="LeftSagittalAnkleLink"/>
    <child link="LeftHenkeAnkleLink"/>
    <limit effort="82.0" lower="-0.314159265359" upper="0.314159265359" velocity="5.24"/>
  </joint>
  <joint name="LeftInternalHeelJoint" type="fixed">
    <origin xyz="-0.140987770121 -0.0358003865588 -0.0618000086563" rpy="5.0054690685e-15 0.663225115758 6.86835455008e-15"/>
    <axis xyz="0.0 0.0 0.0"/>
    <parent link="LeftHenkeAnkleLink"/>
    <child link="LeftInternalHeel"/>
  </joint>
  <joint name="LeftTransverseHipJoint" type="revolute">
    <origin xyz="-0.135 0.169 0.0" rpy="0.0 0.0 0.0"/>
    <axis xyz="0.0 0.0 1.0"/>
    <parent link="LeftFrontalHipLink"/>
    <child link="LeftTransverseHipLink"/>
    <limit effort="180.0" lower="-0.174532925199" upper="0.349065850399" velocity="4.18879020479"/>
  </joint>
  <joint name="RightSagittalKneeJoint" type="revolute">
    <origin xyz="2.55216511342e-16 0.00282404490086 -0.443" rpy="-2.82796112163e-18 -1.83423275819e-28 1.65504327773e-28"/>
    <axis xyz="0.0 1.0 0.0"/>
    <parent link="RightSagittalHipLink"/>
    <child link="RightSagittalKneeLink"/>
    <limit effort="219.0" lower="0.0" upper="1.91986217719" velocity="4.18879020479"/>
  </joint>
  <joint name="LeftToeJoint" type="revolute">
    <origin xyz="0.120631831589 0.0 -0.254503323737" rpy="1.17526109493e-17 0.663225115758 -3.52223310261e-17"/>
    <axis xyz="0.0 1.0 0.0"/>
    <parent link="LeftHenkeAnkleLink"/>
    <child link="LeftToeLink"/>
    <limit effort="1000.0" lower="-1.57079632679" upper="1.57079632679" velocity="1000.0"/>
  </joint>
  <joint name="RightFrontalHipJoint" type="revolute">
    <origin xyz="0.0 -0.089 0.0" rpy="0.0 0.0 0.0"/>
    <axis xyz="1.0 0.0 0.0"/>
    <parent link="PelvisLink"/>
    <child link="RightFrontalHipLink"/>
    <limit effort="350.0" lower="-0.296705972839" upper="0.174532925199" velocity="2.61799387799"/>
  </joint>
  <joint name="PelvisIMUJoint" type="fixed">
    <origin xyz="-0.16444732206 -0.014625 0.194795" rpy="-1.57079632679 0.0 1.57079632679"/>
    <axis xyz="0.0 0.0 0.0"/>
    <parent link="PelvisLink"/>
    <child link="PelvisIMU"/>
  </joint>
  <joint name="LeftExternalHeelJoint" type="fixed">
    <origin xyz="-0.140987770121 0.0357996134412 -0.0618000086563" rpy="5.0054690685e-15 0.663225115758 6.86835455008e-15"/>
    <axis xyz="0.0 0.0 0.0"/>
    <parent link="LeftHenkeAnkleLink"/>
    <child link="LeftExternalHeel"/>
  </joint>
  <joint name="RightExternalHeelJoint" type="fixed">
    <origin xyz="-0.140987770121 -0.0358003865588 -0.0618000086563" rpy="-1.82430889353e-15 0.663225115758 -1.58500489617e-15"/>
    <axis xyz="0.0 0.0 0.0"/>
    <parent link="RightHenkeAnkleLink"/>
    <child link="RightExternalHeel"/>
  </joint>
  <joint name="RightSagittalAnkleJoint" type="revolute">
    <origin xyz="-3.76525155906e-05 0.169418968161 -0.418" rpy="-1.04083408559e-16 -1.46279691175e-17 -0.13962634016"/>
    <axis xyz="0.0 1.0 0.0"/>
    <parent link="RightSagittalKneeLink"/>
    <child link="RightSagittalAnkleLink"/>
    <limit effort="184.0" lower="-0.279252680319" upper="0.157079632679" velocity="3.14"/>
  </joint>
  <joint name="ThoraxIMUJoint" type="fixed">
    <origin xyz="-0.14 0.0 0.5" rpy="0.0 1.57079632679 0.0"/>
    <axis xyz="0.0 0.0 0.0"/>
    <parent link="PelvisLink"/>
    <child link="ThoraxIMU"/>
  </joint>
  <joint name="LeftSagittalAnkleJoint" type="revolute">
    <origin xyz="0.0 -0.169418968161 -0.418" rpy="0.0 -0.0 0.13962634016"/>
    <axis xyz="0.0 1.0 0.0"/>
    <parent link="LeftSagittalKneeLink"/>
    <child link="LeftSagittalAnkleLink"/>
    <limit effort="184.0" lower="-0.279252680319" upper="0.157079632679" velocity="3.14"/>
  </joint>
  <joint name="LeftSagittalKneeJoint" type="revolute">
    <origin xyz="1.27588269137e-16 -0.00282404490086 -0.443" rpy="2.82796112163e-18 1.16200934121e-28 -2.05977408211e-28"/>
    <axis xyz="0.0 1.0 0.0"/>
    <parent link="LeftSagittalHipLink"/>
    <child link="LeftSagittalKneeLink"/>
    <limit effort="219.0" lower="0.0" upper="1.91986217719" velocity="4.18879020479"/>
  </joint>
  <joint name="RightTibiaIMUJoint" type="fixed">
    <origin xyz="-0.115717498003 0.0715975226618 -0.362475" rpy="-1.57079632679 -0.0 0.0"/>
    <axis xyz="0.0 0.0 0.0"/>
    <parent link="RightSagittalKneeLink"/>
    <child link="RightTibiaIMU"/>
  </joint>
  <joint name="LeftSagittalHipJoint" type="revolute">
    <origin xyz="0.135 0.0 0.0" rpy="0.0 0.0 0.0"/>
    <axis xyz="0.0 1.0 0.0"/>
    <parent link="LeftTransverseHipLink"/>
    <child link="LeftSagittalHipLink"/>
    <limit effort="219.0" lower="-2.00712863979" upper="0.0872664625997" velocity="4.18879020479"/>
  </joint>
  <joint name="SittingPointJoint" type="fixed">
    <origin xyz="-0.173617 0.0 -0.076" rpy="0.0 0.0 0.0"/>
    <axis xyz="0.0 0.0 0.0"/>
    <parent link="PelvisLink"/>
    <child link="SittingPoint"/>
  </joint>
  <joint name="RightSagittalHipJoint" type="revolute">
    <origin xyz="0.135 0.0 0.0" rpy="0.0 0.0 0.0"/>
    <axis xyz="0.0 1.0 0.0"/>
    <parent link="RightTransverseHipLink"/>
    <child link="RightSagittalHipLink"/>
    <limit effort="219.0" lower="-2.00712863979" upper="0.0872664625997" velocity="4.18879020479"/>
  </joint>
  <joint name="LeftHeelJoint" type="fixed">
    <origin xyz="-0.172316412469 0.0 -0.0614347367779" rpy="1.17526109493e-17 0.663225115758 -3.52223310261e-17"/>
    <axis xyz="0.0 0.0 0.0"/>
    <parent link="LeftHenkeAnkleLink"/>
    <child link="LeftHeel"/>
  </joint>
  <joint name="RightToeJoint" type="revolute">
    <origin xyz="0.120631831589 0.0 -0.254503323737" rpy="1.58358451956e-18 0.663225115758 -1.8092540875e-33"/>
    <axis xyz="0.0 1.0 0.0"/>
    <parent link="RightHenkeAnkleLink"/>
    <child link="RightToeLink"/>
    <limit effort="1000.0" lower="-1.57079632679" upper="1.57079632679" velocity="1000.0"/>
  </joint>
  <joint name="RightTransverseHipJoint" type="revolute">
    <origin xyz="-0.135 -0.169 0.0" rpy="0.0 0.0 0.0"/>
    <axis xyz="0.0 0.0 1.0"/>
    <parent link="RightFrontalHipLink"/>
    <child link="RightTransverseHipLink"/>
    <limit effort="180.0" lower="-0.349065850399" upper="0.174532925199" velocity="4.18879020479"/>
  </joint>
  <joint name="LeftTibiaIMUJoint" type="fixed">
    <origin xyz="-0.14092 -0.0714975226618 -0.362475" rpy="-1.57079632679 -0.0 -3.14159265359"/>
    <axis xyz="0.0 0.0 0.0"/>
    <parent link="LeftSagittalKneeLink"/>
    <child link="LeftTibiaIMU"/>
  </joint>
  <joint name="LeftSoleJoint" type="fixed">
    <origin xyz="-0.0951195809312 0.0 -0.121747511671" rpy="1.17526109493e-17 0.663225115758 -3.52223310261e-17"/>
    <axis xyz="0.0 0.0 0.0"/>
    <parent link="LeftHenkeAnkleLink"/>
    <child link="LeftSole"/>
  </joint>
  <joint name="RightHeelJoint" type="fixed">
    <origin xyz="-0.172316412469 0.0 -0.0614347367779" rpy="1.58358451956e-18 0.663225115758 -1.8092540875e-33"/>
    <axis xyz="0.0 0.0 0.0"/>
    <parent link="RightHenkeAnkleLink"/>
    <child link="RightHeel"/>
  </joint>
  <joint name="LeftMetatarsusJoint" type="fixed">
    <origin xyz="0.103821248695 0.0 -0.277177122383" rpy="1.17526109493e-17 0.663225115758 -3.52223310261e-17"/>
    <axis xyz="0.0 0.0 0.0"/>
    <parent link="LeftHenkeAnkleLink"/>
    <child link="LeftMetatarsus"/>
  </joint>
  <joint name="RightHenkeAnkleJoint" type="revolute">
    <origin xyz="0.0 0.0 0.0" rpy="0.0 -0.663225115758 6.73695650048e-18"/>
    <axis xyz="1.0 0.0 0.0"/>
    <parent link="RightSagittalAnkleLink"/>
    <child link="RightHenkeAnkleLink"/>
    <limit effort="82.0" lower="-0.314159265359" upper="0.314159265359" velocity="5.24"/>
  </joint>
  <joint name="RightSoleJoint" type="fixed">
    <origin xyz="-0.0951195809312 0.0 -0.121747511671" rpy="1.58358451956e-18 0.663225115758 -1.8092540875e-33"/>
    <axis xyz="0.0 0.0 0.0"/>
    <parent link="RightHenkeAnkleLink"/>
    <child link="RightSole"/>
  </joint>
  <joint name="RightInternalToeJoint" type="fixed">
    <origin xyz="0.0958867916141 0.0358003865588 -0.246866699025" rpy="-1.82430889353e-15 0.663225115758 -1.58500489617e-15"/>
    <axis xyz="0.0 0.0 0.0"/>
    <parent link="RightHenkeAnkleLink"/>
    <child link="RightInternalToe"/>
  </joint>
  <joint name="LeftInternalToeJoint" type="fixed">
    <origin xyz="0.0958882624132 -0.0358003865588 -0.246867848139" rpy="5.0054690685e-15 0.663225115758 6.86835455008e-15"/>
    <axis xyz="0.0 0.0 0.0"/>
    <parent link="LeftHenkeAnkleLink"/>
    <child link="LeftInternalToe"/>
  </joint>
  <joint name="RightInternalHeelJoint" type="fixed">
    <origin xyz="-0.140987770121 0.0357996134412 -0.0618000086563" rpy="-1.82430889353e-15 0.663225115758 -1.58500489617e-15"/>
    <axis xyz="0.0 0.0 0.0"/>
    <parent link="RightHenkeAnkleLink"/>
    <child link="RightInternalHeel"/>
  </joint>
  <joint name="RightExternalToeJoint" type="fixed">
    <origin xyz="0.0958882624132 -0.0358003865588 -0.246867848139" rpy="-1.82430889353e-15 0.663225115758 -1.58500489617e-15"/>
    <axis xyz="0.0 0.0 0.0"/>
    <parent link="RightHenkeAnkleLink"/>
    <child link="RightExternalToe"/>
  </joint>
  <link name="RightInternalToe"/>
  <link name="LeftInternalToe"/>
  <link name="LeftFrontalHipLink">
    <inertial>
      <origin xyz="-0.186571553744 0.0906063837322 0.018559464179" rpy="0.0 0.0 0.0"/>
      <mass value="4.57711244457"/>
      <inertia ixx="0.0387168804333" ixy="-0.0128652224671" ixz="-0.00380927459525" iyy="0.0158320053309" iyz="-0.00693000395231" izz="0.0440775421582"/>
    </inertial>
    <visual>
      <origin xyz="0.0 0.0 0.0" rpy="0.0 0.0 0.0"/>
      <geometry>
        <mesh filename="/home/builder/wdc_workspace/src/jiminy/wdc/data/atalante_with_patient/LeftFrontalHipLink.STL"/>
      </geometry>
      <material name="">
        <color rgba="0.752941176471 0.752941176471 0.752941176471 1.0"/>
      </material>
    </visual>
    <collision>
      <origin xyz="0.0 0.0 0.0" rpy="0.0 0.0 0.0"/>
      <geometry>
        <mesh filename="/home/builder/wdc_workspace/src/jiminy/wdc/data/atalante_with_patient/LeftFrontalHipLink.STL"/>
      </geometry>
    </collision>
  </link>
  <link name="RightExternalToe"/>
  <link name="LeftTibiaIMU"/>
  <link name="RightSagittalHipLink">
    <inertial>
      <origin xyz="0.0130595639063 0.0456975998815 -0.203500775957" rpy="0.0 0.0 0.0"/>
      <mass value="16.3550256947"/>
      <inertia ixx="0.40479389223765316" ixy="0.010413481442573744" ixz="0.0009454024234453412" iyy="0.40277146821417664" iyz="0.008703147924945856" izz="0.06446013712846323"/>
    </inertial>
    <visual>
      <origin xyz="0.0 0.0 0.0" rpy="0.0 0.0 0.0"/>
      <geometry>
        <mesh filename="/home/builder/wdc_workspace/src/jiminy/wdc/data/atalante_with_patient/RightSagittalHipLink.STL"/>
      </geometry>
      <material name="">
        <color rgba="0.752941176471 0.752941176471 0.752941176471 1.0"/>
      </material>
    </visual>
    <collision>
      <origin xyz="0.0 0.0 0.0" rpy="0.0 0.0 0.0"/>
      <geometry>
        <mesh filename="/home/builder/wdc_workspace/src/jiminy/wdc/data/atalante_with_patient/RightSagittalHipLink.STL"/>
      </geometry>
    </collision>
  </link>
  <link name="LeftSagittalHipLink">
    <inertial>
      <origin xyz="0.0130900767525 -0.0456962341065 -0.203476474307" rpy="0.0 0.0 0.0"/>
      <mass value="16.3450657087"/>
      <inertia ixx="0.40438735343330634" ixy="-0.010386215234520286" ixz="0.0009413308347506068" iyy="0.4024091559935222" iyz="-0.008718184002297987" izz="0.06435445961118541"/>
    </inertial>
    <visual>
      <origin xyz="0.0 0.0 0.0" rpy="0.0 0.0 0.0"/>
      <geometry>
        <mesh filename="/home/builder/wdc_workspace/src/jiminy/wdc/data/atalante_with_patient/LeftSagittalHipLink.STL"/>
      </geometry>
      <material name="">
        <color rgba="0.752941176471 0.752941176471 0.752941176471 1.0"/>
      </material>
    </visual>
    <collision>
      <origin xyz="0.0 0.0 0.0" rpy="0.0 0.0 0.0"/>
      <geometry>
        <mesh filename="/home/builder/wdc_workspace/src/jiminy/wdc/data/atalante_with_patient/LeftSagittalHipLink.STL"/>
      </geometry>
    </collision>
  </link>
  <link name="RightSagittalKneeLink">
    <inertial>
      <origin xyz="-0.0475192283941 0.100401439588 -0.216661166868" rpy="0.0 0.0 0.0"/>
      <mass value="13.0718782422"/>
      <inertia ixx="0.3013389618683471" ixy="0.024566661450206514" ixz="-0.07610509754950806" iyy="0.32598626662009617" iyz="0.043325414247557405" izz="0.10756824112543432"/>
    </inertial>
    <visual>
      <origin xyz="0.0 0.0 0.0" rpy="0.0 0.0 0.0"/>
      <geometry>
        <mesh filename="/home/builder/wdc_workspace/src/jiminy/wdc/data/atalante_with_patient/RightSagittalKneeLink.STL"/>
      </geometry>
      <material name="">
        <color rgba="0.752941176471 0.752941176471 0.752941176471 1.0"/>
      </material>
    </visual>
    <collision>
      <origin xyz="0.0 0.0 0.0" rpy="0.0 0.0 0.0"/>
      <geometry>
        <mesh filename="/home/builder/wdc_workspace/src/jiminy/wdc/data/atalante_with_patient/RightSagittalKneeLink.STL"/>
      </geometry>
    </collision>
  </link>
  <link name="RightHenkeAnkleLink">
    <inertial>
      <origin xyz="-0.000474131327287 -0.0231850732208 -0.121834434375" rpy="0.0 0.0 0.0"/>
      <mass value="3.28178964662"/>
      <inertia ixx="0.04010978309370759" ixy="0.007077953212571446" ixz="0.016603638154222958" iyy="0.06663086262420038" iyz="-0.0003708048959431931" izz="0.038956472443801723"/>
    </inertial>
    <visual>
      <origin xyz="0.0 0.0 0.0" rpy="0.0 0.0 0.0"/>
      <geometry>
        <mesh filename="/home/builder/wdc_workspace/src/jiminy/wdc/data/atalante_with_patient/RightHenkeAnkleLink.STL"/>
      </geometry>
      <material name="">
        <color rgba="0.752941176471 0.752941176471 0.752941176471 1.0"/>
      </material>
    </visual>
    <collision>
      <origin xyz="0.0 0.0 0.0" rpy="0.0 0.0 0.0"/>
      <geometry>
        <mesh filename="/home/builder/wdc_workspace/src/jiminy/wdc/data/atalante_with_patient/RightHenkeAnkleLink.STL"/>
      </geometry>
    </collision>
  </link>
  <link name="LeftHeel"/>
  <link name="LeftMetatarsus"/>
  <link name="LeftInternalHeel"/>
  <link name="PelvisIMU"/>
  <link name="LeftTransverseHipLink">
    <inertial>
      <origin xyz="0.0683758079388 -0.012644594049 6.8497004039e-05" rpy="0.0 0.0 0.0"/>
      <mass value="3.58270096733"/>
      <inertia ixx="0.00477435966476" ixy="0.0028407458755" ixz="-0.000174789103955" iyy="0.0204089629263" iyz="7.10508990985e-06" izz="0.0210649799523"/>
    </inertial>
    <visual>
      <origin xyz="0.0 0.0 0.0" rpy="0.0 0.0 0.0"/>
      <geometry>
        <mesh filename="/home/builder/wdc_workspace/src/jiminy/wdc/data/atalante_with_patient/LeftTransverseHipLink.STL"/>
      </geometry>
      <material name="">
        <color rgba="0.752941176471 0.752941176471 0.752941176471 1.0"/>
      </material>
    </visual>
    <collision>
      <origin xyz="0.0 0.0 0.0" rpy="0.0 0.0 0.0"/>
      <geometry>
        <mesh filename="/home/builder/wdc_workspace/src/jiminy/wdc/data/atalante_with_patient/LeftTransverseHipLink.STL"/>
      </geometry>
    </collision>
  </link>
  <link name="RightSole"/>
  <link name="LeftExternalHeel"/>
  <link name="LeftExternalToe"/>
  <link name="LeftToeLink">
    <inertial>
      <origin xyz="-0.02 0.0 -0.0131697791352" rpy="0.0 0.0 0.0"/>
      <mass value="0.000924393016291"/>
      <inertia ixx="1.06463836233e-08" ixy="-5.16987882846e-25" ixz="-3.86675116289e-23" iyy="1.06463836233e-08" iyz="4.38100899412e-23" izz="2.5123795073e-09"/>
    </inertial>
    <visual>
      <origin xyz="0.0 0.0 0.0" rpy="0.0 0.0 0.0"/>
      <geometry>
        <mesh filename="/home/builder/wdc_workspace/src/jiminy/wdc/data/atalante_with_patient/LeftToeLink.STL"/>
      </geometry>
      <material name="">
        <color rgba="0.776470588235 0.756862745098 0.737254901961 1.0"/>
      </material>
    </visual>
    <collision>
      <origin xyz="0.0 0.0 0.0" rpy="0.0 0.0 0.0"/>
      <geometry>
        <mesh filename="/home/builder/wdc_workspace/src/jiminy/wdc/data/atalante_with_patient/LeftToeLink.STL"/>
      </geometry>
    </collision>
  </link>
  <link name="SittingPoint"/>
  <link name="RightTibiaIMU"/>
  <link name="LeftSagittalAnkleLink">
    <inertial>
      <origin xyz="-0.0449311849249 0.0536312060439 -0.0397299264147" rpy="0.0 0.0 0.0"/>
      <mass value="1.6795903453"/>
      <inertia ixx="0.00462561315468" ixy="-0.0021759198084" ixz="-0.00171467862072" iyy="0.0042443274057" iyz="-0.00157978926793" izz="0.0053986646312"/>
    </inertial>
    <visual>
      <origin xyz="0.0 0.0 0.0" rpy="0.0 0.0 0.0"/>
      <geometry>
        <mesh filename="/home/builder/wdc_workspace/src/jiminy/wdc/data/atalante_with_patient/LeftSagittalAnkleLink.STL"/>
      </geometry>
      <material name="">
        <color rgba="0.752941176471 0.752941176471 0.752941176471 1.0"/>
      </material>
    </visual>
    <collision>
      <origin xyz="0.0 0.0 0.0" rpy="0.0 0.0 0.0"/>
      <geometry>
        <mesh filename="/home/builder/wdc_workspace/src/jiminy/wdc/data/atalante_with_patient/LeftSagittalAnkleLink.STL"/>
      </geometry>
    </collision>
  </link>
  <link name="LeftSagittalKneeLink">
    <inertial>
      <origin xyz="-0.0473385005758 -0.100692316088 -0.216747801854" rpy="0.0 0.0 0.0"/>
      <mass value="13.076827503"/>
      <inertia ixx="0.3014537934661905" ixy="-0.024662117458788848" ixz="-0.07534721850084364" iyy="0.32536584183974304" iyz="-0.0437733517084595" izz="0.10761264470379794"/>
    </inertial>
    <visual>
      <origin xyz="0.0 0.0 0.0" rpy="0.0 0.0 0.0"/>
      <geometry>
        <mesh filename="/home/builder/wdc_workspace/src/jiminy/wdc/data/atalante_with_patient/LeftSagittalKneeLink.STL"/>
      </geometry>
      <material name="">
        <color rgba="0.650980392157 0.619607843137 0.588235294118 1.0"/>
      </material>
    </visual>
    <collision>
      <origin xyz="0.0 0.0 0.0" rpy="0.0 0.0 0.0"/>
      <geometry>
        <mesh filename="/home/builder/wdc_workspace/src/jiminy/wdc/data/atalante_with_patient/LeftSagittalKneeLink.STL"/>
      </geometry>
    </collision>
  </link>
  <link name="ThoraxIMU"/>
  <link name="RightTransverseHipLink">
    <inertial>
      <origin xyz="0.0683722382329 0.0126452921342 6.85203783712e-05" rpy="0.0 0.0 0.0"/>
      <mass value="3.58272247539"/>
      <inertia ixx="0.00476812318531" ixy="-0.00284077044411" ixz="-0.000191965139473" iyy="0.0204084146541" iyz="-7.07606178969e-06" izz="0.0210703848852"/>
    </inertial>
    <visual>
      <origin xyz="0.0 0.0 0.0" rpy="0.0 0.0 0.0"/>
      <geometry>
        <mesh filename="/home/builder/wdc_workspace/src/jiminy/wdc/data/atalante_with_patient/RightTransverseHipLink.STL"/>
      </geometry>
      <material name="">
        <color rgba="0.752941176471 0.752941176471 0.752941176471 1.0"/>
      </material>
    </visual>
    <collision>
      <origin xyz="0.0 0.0 0.0" rpy="0.0 0.0 0.0"/>
      <geometry>
        <mesh filename="/home/builder/wdc_workspace/src/jiminy/wdc/data/atalante_with_patient/RightTransverseHipLink.STL"/>
      </geometry>
    </collision>
  </link>
  <link name="RightSagittalAnkleLink">
    <inertial>
      <origin xyz="-0.0449312544425 -0.0536312625226 -0.0397298889258" rpy="0.0 0.0 0.0"/>
      <mass value="1.67959242825"/>
      <inertia ixx="0.00462559827788" ixy="0.00217592019173" ixz="-0.00171467729365" iyy="0.0042443360754" iyz="0.00157978666903" izz="0.00539865721698"/>
    </inertial>
    <visual>
      <origin xyz="0.0 0.0 0.0" rpy="0.0 0.0 0.0"/>
      <geometry>
        <mesh filename="/home/builder/wdc_workspace/src/jiminy/wdc/data/atalante_with_patient/RightSagittalAnkleLink.STL"/>
      </geometry>
      <material name="">
        <color rgba="0.752941176471 0.752941176471 0.752941176471 1.0"/>
      </material>
    </visual>
    <collision>
      <origin xyz="0.0 0.0 0.0" rpy="0.0 0.0 0.0"/>
      <geometry>
        <mesh filename="/home/builder/wdc_workspace/src/jiminy/wdc/data/atalante_with_patient/RightSagittalAnkleLink.STL"/>
      </geometry>
    </collision>
  </link>
  <link name="LeftHenkeAnkleLink">
    <inertial>
      <origin xyz="-0.0004838668936 0.02295738198 -0.121826828536" rpy="0.0 0.0 0.0"/>
      <mass value="3.28178968035"/>
      <inertia ixx="0.04014482688293192" ixy="-0.007058663651098434" ixz="0.016601161073659394" iyy="0.06662466780519984" iyz="0.00032404454232834565" izz="0.0389857793301175"/>
    </inertial>
    <visual>
      <origin xyz="0.0 0.0 0.0" rpy="0.0 0.0 0.0"/>
      <geometry>
        <mesh filename="/home/builder/wdc_workspace/src/jiminy/wdc/data/atalante_with_patient/LeftHenkeAnkleLink.STL"/>
      </geometry>
      <material name="">
        <color rgba="0.752941176471 0.752941176471 0.752941176471 1.0"/>
      </material>
    </visual>
    <collision>
      <origin xyz="0.0 0.0 0.0" rpy="0.0 0.0 0.0"/>
      <geometry>
        <mesh filename="/home/builder/wdc_workspace/src/jiminy/wdc/data/atalante_with_patient/LeftHenkeAnkleLink.STL"/>
      </geometry>
    </collision>
  </link>
  <link name="PelvisLink">
    <inertial>
      <origin xyz="-0.039641628881 0.00016061167625 0.284363946426" rpy="0.0 0.0 0.0"/>
      <mass value="64.7208256049"/>
      <inertia ixx="4.673324866764113" ixy="0.00142246315825594" ixz="-0.3338192534713498" iyy="4.5106170235453416" iyz="-0.0010557732608934896" izz="0.9423864824398385"/>
    </inertial>
    <visual>
      <origin xyz="0.0 0.0 0.0" rpy="0.0 0.0 0.0"/>
      <geometry>
        <mesh filename="/home/builder/wdc_workspace/src/jiminy/wdc/data/atalante_with_patient/PelvisLink.STL"/>
      </geometry>
      <material name="">
        <color rgba="0.752941176471 0.752941176471 0.752941176471 1.0"/>
      </material>
    </visual>
    <collision>
      <origin xyz="0.0 0.0 0.0" rpy="0.0 0.0 0.0"/>
      <geometry>
        <mesh filename="/home/builder/wdc_workspace/src/jiminy/wdc/data/atalante_with_patient/PelvisLink.STL"/>
      </geometry>
    </collision>
  </link>
  <link name="RightInternalHeel"/>
  <link name="LeftSole"/>
  <link name="RightHeel"/>
  <link name="RightFrontalHipLink">
    <inertial>
      <origin xyz="-0.186547774384 -0.0905204864245 0.0187848514032" rpy="0.0 0.0 0.0"/>
      <mass value="4.57749153969"/>
      <inertia ixx="0.0387820391042" ixy="0.0128746737715" ixz="-0.0038608540806" iyy="0.0159077827844" iyz="0.00698748992322" izz="0.0440807173609"/>
    </inertial>
    <visual>
      <origin xyz="0.0 0.0 0.0" rpy="0.0 0.0 0.0"/>
      <geometry>
        <mesh filename="/home/builder/wdc_workspace/src/jiminy/wdc/data/atalante_with_patient/RightFrontalHipLink.STL"/>
      </geometry>
      <material name="">
        <color rgba="0.752941176471 0.752941176471 0.752941176471 1.0"/>
      </material>
    </visual>
    <collision>
      <origin xyz="0.0 0.0 0.0" rpy="0.0 0.0 0.0"/>
      <geometry>
        <mesh filename="/home/builder/wdc_workspace/src/jiminy/wdc/data/atalante_with_patient/RightFrontalHipLink.STL"/>
      </geometry>
    </collision>
  </link>
  <link name="RightMetatarsus"/>
  <link name="RightToeLink">
    <inertial>
      <origin xyz="-0.02 9.71445146547e-17 -0.0131697791352" rpy="0.0 0.0 0.0"/>
      <mass value="0.000924393016291"/>
      <inertia ixx="1.06463836233e-08" ixy="-4.13590306277e-25" ixz="-6.04406594907e-23" iyy="1.06463836233e-08" iyz="3.10386970138e-24" izz="2.5123795073e-09"/>
    </inertial>
    <visual>
      <origin xyz="0.0 0.0 0.0" rpy="0.0 0.0 0.0"/>
      <geometry>
        <mesh filename="/home/builder/wdc_workspace/src/jiminy/wdc/data/atalante_with_patient/RightToeLink.STL"/>
      </geometry>
      <material name="">
        <color rgba="0.776470588235 0.756862745098 0.737254901961 1.0"/>
      </material>
    </visual>
    <collision>
      <origin xyz="0.0 0.0 0.0" rpy="0.0 0.0 0.0"/>
      <geometry>
        <mesh filename="/home/builder/wdc_workspace/src/jiminy/wdc/data/atalante_with_patient/RightToeLink.STL"/>
      </geometry>
    </collision>
  </link>
  <link name="RightExternalHeel"/>
  <gazebo>
    <plugin filename="libwdc_simulation.so" name="wanderbrainPlugin"/>
  </gazebo>
  <gazebo reference="PelvisLink">
    <material>Gazebo/Orange</material>
    <sensor name="PelvisIMU" type="imu">
      <visualize>true</visualize>
      <always_on>true</always_on>
      <update_rate>1000</update_rate>
      <pose>-0.16444732206 -0.014625 0.194795 -1.57079632679 0.0 1.57079632679</pose>
    </sensor>
    <sensor name="ThoraxIMU" type="imu">
      <visualize>true</visualize>
      <always_on>true</always_on>
      <update_rate>1000</update_rate>
      <pose>-0.14 0.0 0.5 0.0 1.57079632679 0.0</pose>
    </sensor>
  </gazebo>
  <gazebo reference="RightFrontalHipLink">
    <material>Gazebo/Green</material>
  </gazebo>
  <gazebo reference="RightTransverseHipLink">
    <material>Gazebo/Blue</material>
  </gazebo>
  <gazebo reference="RightSagittalHipLink">
    <material>Gazebo/Yellow</material>
  </gazebo>
  <gazebo reference="RightSagittalKneeLink">
    <material>Gazebo/Red</material>
    <sensor name="RightTibiaIMU" type="imu">
      <visualize>true</visualize>
      <always_on>true</always_on>
      <update_rate>1000</update_rate>
      <pose>-0.115717498003 0.0715975226618 -0.362475 -1.57079632679 -0.0 0.0</pose>
    </sensor>
  </gazebo>
  <gazebo reference="RightSagittalAnkleLink">
    <material>Gazebo/Turquoise</material>
  </gazebo>
  <gazebo reference="RightHenkeAnkleLink">
    <material>Gazebo/Purple</material>
    <kp>1000000.0</kp>
    <kd>2000.0</kd>
    <mu1>1.0</mu1>
    <mu2>1.0</mu2>
    <fdir1>1 0 0</fdir1>
    <maxVel>1.0</maxVel>
    <minDepth>0.00</minDepth>
    <sensor name="RightFootContact" type="contact">
      <visualize>true</visualize>
      <always_on>true</always_on>
      <update_rate>1000</update_rate>
      <contact>
        <collision>RightHenkeAnkleLink_collision</collision>
      </contact>
      <pose>-0.0951195809312 0.0 -0.121747511671 1.58358451956e-18 0.663225115758 -1.8092540875e-33</pose>
    </sensor>
  </gazebo>
  <gazebo reference="RightToeLink">
    <material>Gazebo/Gold</material>
  </gazebo>
  <gazebo reference="LeftFrontalHipLink">
    <material>Gazebo/Green</material>
  </gazebo>
  <gazebo reference="LeftTransverseHipLink">
    <material>Gazebo/Blue</material>
  </gazebo>
  <gazebo reference="LeftSagittalHipLink">
    <material>Gazebo/Yellow</material>
  </gazebo>
  <gazebo reference="LeftSagittalKneeLink">
    <material>Gazebo/Red</material>
    <sensor name="LeftTibiaIMU" type="imu">
      <visualize>true</visualize>
      <always_on>true</always_on>
      <update_rate>1000</update_rate>
      <pose>-0.14092 -0.0714975226618 -0.362475 -1.57079632679 -0.0 -3.14159265359</pose>
    </sensor>
  </gazebo>
  <gazebo reference="LeftSagittalAnkleLink">
    <material>Gazebo/Turquoise</material>
  </gazebo>
  <gazebo reference="LeftHenkeAnkleLink">
    <material>Gazebo/Purple</material>
    <kp>1000000.0</kp>
    <kd>2000.0</kd>
    <mu1>1.0</mu1>
    <mu2>1.0</mu2>
    <fdir1>1 0 0</fdir1>
    <maxVel>1.0</maxVel>
    <minDepth>0.00</minDepth>
    <sensor name="LeftFootContact" type="contact">
      <visualize>true</visualize>
      <always_on>true</always_on>
      <update_rate>1000</update_rate>
      <contact>
        <collision>LeftHenkeAnkleLink_collision</collision>
      </contact>
      <pose>-0.0951195809312 0.0 -0.121747511671 1.17526109493e-17 0.663225115758 -3.52223310261e-17</pose>
    </sensor>
  </gazebo>
  <gazebo reference="LeftToeLink">
    <material>Gazebo/Gold</material>
  </gazebo>
  <transmission name="RightFrontalHipTransmission">
    <type>transmission_interface/SimpleTransmission</type>
    <joint name="RightFrontalHipJoint"/>
    <actuator name="RightFrontalHipMotor">
      <hardwareInterface>EffortJointInterface</hardwareInterface>
      <mechanicalReduction>1.0</mechanicalReduction>
    </actuator>
  </transmission>
  <transmission name="RightTransverseHipTransmission">
    <type>transmission_interface/SimpleTransmission</type>
    <joint name="RightTransverseHipJoint"/>
    <actuator name="RightTransverseHipMotor">
      <hardwareInterface>EffortJointInterface</hardwareInterface>
      <mechanicalReduction>1.0</mechanicalReduction>
    </actuator>
  </transmission>
  <transmission name="RightSagittalHipTransmission">
    <type>transmission_interface/SimpleTransmission</type>
    <joint name="RightSagittalHipJoint"/>
    <actuator name="RightSagittalHipMotor">
      <hardwareInterface>EffortJointInterface</hardwareInterface>
      <mechanicalReduction>1.0</mechanicalReduction>
    </actuator>
  </transmission>
  <transmission name="RightSagittalKneeTransmission">
    <type>transmission_interface/SimpleTransmission</type>
    <joint name="RightSagittalKneeJoint"/>
    <actuator name="RightSagittalKneeMotor">
      <hardwareInterface>EffortJointInterface</hardwareInterface>
      <mechanicalReduction>1.0</mechanicalReduction>
    </actuator>
  </transmission>
  <transmission name="RightSagittalAnkleTransmission">
    <type>transmission_interface/SimpleTransmission</type>
    <joint name="RightSagittalAnkleJoint"/>
    <actuator name="RightSagittalAnkleMotor">
      <hardwareInterface>EffortJointInterface</hardwareInterface>
      <mechanicalReduction>1.0</mechanicalReduction>
    </actuator>
  </transmission>
  <transmission name="RightHenkeAnkleTransmission">
    <type>transmission_interface/SimpleTransmission</type>
    <joint name="RightHenkeAnkleJoint"/>
    <actuator name="RightHenkeAnkleMotor">
      <hardwareInterface>EffortJointInterface</hardwareInterface>
      <mechanicalReduction>1.0</mechanicalReduction>
    </actuator>
  </transmission>
  <transmission name="LeftFrontalHipTransmission">
    <type>transmission_interface/SimpleTransmission</type>
    <joint name="LeftFrontalHipJoint"/>
    <actuator name="LeftFrontalHipMotor">
      <hardwareInterface>EffortJointInterface</hardwareInterface>
      <mechanicalReduction>1.0</mechanicalReduction>
    </actuator>
  </transmission>
  <transmission name="LeftTransverseHipTransmission">
    <type>transmission_interface/SimpleTransmission</type>
    <joint name="LeftTransverseHipJoint"/>
    <actuator name="LeftTransverseHipMotor">
      <hardwareInterface>EffortJointInterface</hardwareInterface>
      <mechanicalReduction>1.0</mechanicalReduction>
    </actuator>
  </transmission>
  <transmission name="LeftSagittalHipTransmission">
    <type>transmission_interface/SimpleTransmission</type>
    <joint name="LeftSagittalHipJoint"/>
    <actuator name="LeftSagittalHipMotor">
      <hardwareInterface>EffortJointInterface</hardwareInterface>
      <mechanicalReduction>1.0</mechanicalReduction>
    </actuator>
  </transmission>
  <transmission name="LeftSagittalKneeTransmission">
    <type>transmission_interface/SimpleTransmission</type>
    <joint name="LeftSagittalKneeJoint"/>
    <actuator name="LeftSagittalKneeMotor">
      <hardwareInterface>EffortJointInterface</hardwareInterface>
      <mechanicalReduction>1.0</mechanicalReduction>
    </actuator>
  </transmission>
  <transmission name="LeftSagittalAnkleTransmission">
    <type>transmission_interface/SimpleTransmission</type>
    <joint name="LeftSagittalAnkleJoint"/>
    <actuator name="LeftSagittalAnkleMotor">
      <hardwareInterface>EffortJointInterface</hardwareInterface>
      <mechanicalReduction>1.0</mechanicalReduction>
    </actuator>
  </transmission>
  <transmission name="LeftHenkeAnkleTransmission">
    <type>transmission_interface/SimpleTransmission</type>
    <joint name="LeftHenkeAnkleJoint"/>
    <actuator name="LeftHenkeAnkleMotor">
      <hardwareInterface>EffortJointInterface</hardwareInterface>
      <mechanicalReduction>1.0</mechanicalReduction>
    </actuator>
  </transmission>
  <patient_info>
    <patient_measurements_version>v5-4</patient_measurements_version>
    <total_mass>149.814261067</total_mass>
    <center_id>{2a1a3110-a274-49d2-bb39-795ec88627b6}</center_id>
    <patient_id>patient_000024</patient_id>
    <is_patient>True</is_patient>
    <patient_height>1.84</patient_height>
    <patient_mass>75</patient_mass>
    <patient_offset_from_exo>0.0</patient_offset_from_exo>
  </patient_info>
</robot>
